Workbook

Sheet スクリプト
A1: =マトリクス!C3 -> wget --user-agent Mozilla/4.0 http://k-db.com/indices/I101/1d/2007?download=csv -O "./日経平均株価_日足_2007.csv"; sleep 4;
A2: =マトリクス!C4 -> wget --user-agent Mozilla/4.0 http://k-db.com/indices/I102/1d/2007?download=csv -O "./TOPIX_日足_2007.csv"; sleep 4;
A3: =マトリクス!C5 -> wget --user-agent Mozilla/4.0 http://k-db.com/indices/I103/1d/2007?download=csv -O "./JPX日経インデックス400_日足_2007.csv"; sleep 4;
A4: =マトリクス!C6 -> wget --user-agent Mozilla/4.0 http://k-db.com/indices/I104/1d/2007?download=csv -O "./東証2部株価指数_日足_2007.csv"; sleep 4;
A5: =マトリクス!C7 -> wget --user-agent Mozilla/4.0 http://k-db.com/indices/I105/1d/2007?download=csv -O "./東証マザーズ指数_日足_2007.csv"; sleep 4;
A6: =マトリクス!C8 -> wget --user-agent Mozilla/4.0 http://k-db.com/indices/I111/1d/2007?download=csv -O "./TOPIX コア 30_日足_2007.csv"; sleep 4;
A7: =マトリクス!C9 -> wget --user-agent Mozilla/4.0 http://k-db.com/indices/I112/1d/2007?download=csv -O "./TOPIX ラージ 70_日足_2007.csv"; sleep 4;
A8: =マトリクス!C10 -> wget --user-agent Mozilla/4.0 http://k-db.com/indices/I113/1d/2007?download=csv -O "./TOPIX 100_日足_2007.csv"; sleep 4;
A9: =マトリクス!C11 -> wget --user-agent Mozilla/4.0 http://k-db.com/indices/I114/1d/2007?download=csv -O "./TOPIX ミッド 400_日足_2007.csv"; sleep 4;
A10: =マトリクス!C12 -> wget --user-agent Mozilla/4.0 http://k-db.com/indices/I115/1d/2007?download=csv -O "./TOPIX 500_日足_2007.csv"; sleep 4;
A11: =マトリクス!C13 -> wget --user-agent Mozilla/4.0 http://k-db.com/indices/I116/1d/2007?download=csv -O "./TOPIX スモール_日足_2007.csv"; sleep 4;
A12: =マトリクス!C14 -> wget --user-agent Mozilla/4.0 http://k-db.com/indices/I117/1d/2007?download=csv -O "./TOPIX 1000_日足_2007.csv"; sleep 4;
... A92: =マトリクス!C94 -> wget --user-agent Mozilla/4.0 http://k-db.com/indices/I306/1d/2007?download=csv -O "./日経ジャスダック平均株価_日足_2007.csv"; sleep 5;
A93: =マトリクス!D3 -> wget --user-agent Mozilla/4.0 http://k-db.com/indices/I101/1d/2008?download=csv -O "./日経平均株価_日足_2008.csv"; sleep 4;
A94: =マトリクス!D4 -> wget --user-agent Mozilla/4.0 http://k-db.com/indices/I102/1d/2008?download=csv -O "./TOPIX_日足_2008.csv"; sleep 4;
A95: =マトリクス!D5 -> wget --user-agent Mozilla/4.0 http://k-db.com/indices/I103/1d/2008?download=csv -O "./JPX日経インデックス400_日足_2008.csv"; sleep 4;
A96: =マトリクス!D6 -> wget --user-agent Mozilla/4.0 http://k-db.com/indices/I104/1d/2008?download=csv -O "./東証2部株価指数_日足_2008.csv"; sleep 4;
A97: =マトリクス!D7 -> wget --user-agent Mozilla/4.0 http://k-db.com/indices/I105/1d/2008?download=csv -O "./東証マザーズ指数_日足_2008.csv"; sleep 4;
A98: =マトリクス!D8 -> wget --user-agent Mozilla/4.0 http://k-db.com/indices/I111/1d/2008?download=csv -O "./TOPIX コア 30_日足_2008.csv"; sleep 4;
A99: =マトリクス!D9 -> wget --user-agent Mozilla/4.0 http://k-db.com/indices/I112/1d/2008?download=csv -O "./TOPIX ラージ 70_日足_2008.csv"; sleep 4;
A100: =マトリクス!D10 -> wget --user-agent Mozilla/4.0 http://k-db.com/indices/I113/1d/2008?download=csv -O "./TOPIX 100_日足_2008.csv"; sleep 4;
A101: =マトリクス!D11 -> wget --user-agent Mozilla/4.0 http://k-db.com/indices/I114/1d/2008?download=csv -O "./TOPIX ミッド 400_日足_2008.csv"; sleep 4;
A102: =マトリクス!D12 -> wget --user-agent Mozilla/4.0 http://k-db.com/indices/I115/1d/2008?download=csv -O "./TOPIX 500_日足_2008.csv"; sleep 4;
A103: =マトリクス!D13 -> wget --user-agent Mozilla/4.0 http://k-db.com/indices/I116/1d/2008?download=csv -O "./TOPIX スモール_日足_2008.csv"; sleep 4;
A104: =マトリクス!D14 -> wget --user-agent Mozilla/4.0 http://k-db.com/indices/I117/1d/2008?download=csv -O "./TOPIX 1000_日足_2008.csv"; sleep 4;
... A184: =マトリクス!D94 -> wget --user-agent Mozilla/4.0 http://k-db.com/indices/I306/1d/2008?download=csv -O "./日経ジャスダック平均株価_日足_2008.csv"; sleep 5;
A185: =マトリクス!E3 -> wget --user-agent Mozilla/4.0 http://k-db.com/indices/I101/1d/2009?download=csv -O "./日経平均株価_日足_2009.csv"; sleep 4;
A186: =マトリクス!E4 -> wget --user-agent Mozilla/4.0 http://k-db.com/indices/I102/1d/2009?download=csv -O "./TOPIX_日足_2009.csv"; sleep 4;
A187: =マトリクス!E5 -> wget --user-agent Mozilla/4.0 http://k-db.com/indices/I103/1d/2009?download=csv -O "./JPX日経インデックス400_日足_2009.csv"; sleep 4;
A188: =マトリクス!E6 -> wget --user-agent Mozilla/4.0 http://k-db.com/indices/I104/1d/2009?download=csv -O "./東証2部株価指数_日足_2009.csv"; sleep 4;
A189: =マトリクス!E7 -> wget --user-agent Mozilla/4.0 http://k-db.com/indices/I105/1d/2009?download=csv -O "./東証マザーズ指数_日足_2009.csv"; sleep 4;
A190: =マトリクス!E8 -> wget --user-agent Mozilla/4.0 http://k-db.com/indices/I111/1d/2009?download=csv -O "./TOPIX コア 30_日足_2009.csv"; sleep 4;
A191: =マトリクス!E9 -> wget --user-agent Mozilla/4.0 http://k-db.com/indices/I112/1d/2009?download=csv -O "./TOPIX ラージ 70_日足_2009.csv"; sleep 4;
A192: =マトリクス!E10 -> wget --user-agent Mozilla/4.0 http://k-db.com/indices/I113/1d/2009?download=csv -O "./TOPIX 100_日足_2009.csv"; sleep 4;
A193: =マトリクス!E11 -> wget --user-agent Mozilla/4.0 http://k-db.com/indices/I114/1d/2009?download=csv -O "./TOPIX ミッド 400_日足_2009.csv"; sleep 4;
A194: =マトリクス!E12 -> wget --user-agent Mozilla/4.0 http://k-db.com/indices/I115/1d/2009?download=csv -O "./TOPIX 500_日足_2009.csv"; sleep 4;
A195: =マトリクス!E13 -> wget --user-agent Mozilla/4.0 http://k-db.com/indices/I116/1d/2009?download=csv -O "./TOPIX スモール_日足_2009.csv"; sleep 4;
A196: =マトリクス!E14 -> wget --user-agent Mozilla/4.0 http://k-db.com/indices/I117/1d/2009?download=csv -O "./TOPIX 1000_日足_2009.csv"; sleep 4;
... A276: =マトリクス!E94 -> wget --user-agent Mozilla/4.0 http://k-db.com/indices/I306/1d/2009?download=csv -O "./日経ジャスダック平均株価_日足_2009.csv"; sleep 5;
A277: =マトリクス!F3 -> wget --user-agent Mozilla/4.0 http://k-db.com/indices/I101/1d/2010?download=csv -O "./日経平均株価_日足_2010.csv"; sleep 4;
...

Sheet マトリクス
A1: 銘柄 | B1: DL元ディレクトリ | C1: 日足 | N1: 前場後場
C2: 2007 | D2: 2008 | E2: 2009 | F2: 2010 | G2: 2011 | H2: 2012 | I2: 2013 | J2: 2014 | K2: 2015 | L2: 2016 | M2: 2017 | N2: 2007 | O2: 2008 | P2: 2009 | Q2: 2010 | R2: 2011 | S2: 2012 | T2: 2013 | U2: 2014 | V2: 2015 | W2: 2016 | X2: 2017
A3: 日経平均株価 | B3: /indices/I101 | C3: ="wget --user-agent Mozilla/4.0 http://k-db.com" & $B3 & "/1d/" & C$2 & "?download=csv -O ""./" & $A3 & "_" & $C$1 & "_" & C$2 & ".csv""; sleep 4;" -> wget --user-agent Mozilla/4.0 http://k-db.com/indices/I101/1d/2007?download=csv -O "./日経平均株価_日足_2007.csv"; sleep 4; | D3: ="wget --user-agent Mozilla/4.0 http://k-db.com" & $B3 & "/1d/" & D$2 & "?download=csv -O ""./" & $A3 & "_" & $C$1 & "_" & D$2 & ".csv""; sleep 4;" -> wget --user-agent Mozilla/4.0 http://k-db.com/indices/I101/1d/2008?download=csv -O "./日経平均株価_日足_2008.csv"; sleep 4; | E3: ="wget --user-agent Mozilla/4.0 http://k-db.com" & $B3 & "/1d/" & E$2 & "?download=csv -O ""./" & $A3 & "_" & $C$1 & "_" & E$2 & ".csv""; sleep 4;" -> wget --user-agent Mozilla/4.0 http://k-db.com/indices/I101/1d/2009?download=csv -O "./日経平均株価_日足_2009.csv"; sleep 4; | F3: ="wget --user-agent Mozilla/4.0 http://k-db.com" & $B3 & "/1d/" & F$2 & "?download=csv -O ""./" & $A3 & "_" & $C$1 & "_" & F$2 & ".csv""; sleep 4;" -> wget --user-agent Mozilla/4.0 http://k-db.com/indices/I101/1d/2010?download=csv -O "./日経平均株価_日足_2010.csv"; sleep 4; | G3: ="wget --user-agent Mozilla/4.0 http://k-db.com" & $B3 & "/1d/" & G$2 & "?download=csv -O ""./" & $A3 & "_" & $C$1 & "_" & G$2 & ".csv""; sleep 4;" -> wget --user-agent Mozilla/4.0 http://k-db.com/indices/I101/1d/2011?download=csv -O "./日経平均株価_日足_2011.csv"; sleep 4; | H3: ="wget --user-agent Mozilla/4.0 http://k-db.com" & $B3 & "/1d/" & H$2 & "?download=csv -O ""./" & $A3 & "_" & $C$1 & "_" & H$2 & ".csv""; sleep 4;" -> wget --user-agent Mozilla/4.0 http://k-db.com/indices/I101/1d/2012?download=csv -O "./日経平均株価_日足_2012.csv"; sleep 4; | I3: ="wget --user-agent Mozilla/4.0 http://k-db.com" & $B3 & "/1d/" & I$2 & "?download=csv -O ""./" & $A3 & "_" & $C$1 & "_" & I$2 & ".csv""; sleep 4;" -> wget --user-agent Mozilla/4.0 http://k-db.com/indices/I101/1d/2013?download=csv -O "./日経平均株価_日足_2013.csv"; sleep 4; | J3: ="wget --user-agent Mozilla/4.0 http://k-db.com" & $B3 & "/1d/" & J$2 & "?download=csv -O ""./" & $A3 & "_" & $C$1 & "_" & J$2 & ".csv""; sleep 4;" -> wget --user-agent Mozilla/4.0 http://k-db.com/indices/I101/1d/2014?download=csv -O "./日経平均株価_日足_2014.csv"; sleep 4; | ... M3: ="wget --user-agent Mozilla/4.0 http://k-db.com" & $B3 & "/1d/" & M$2 & "?download=csv -O ""./" & $A3 & "_" & $C$1 & "_" & M$2 & ".csv""; sleep 4;" -> wget --user-agent Mozilla/4.0 http://k-db.com/indices/I101/1d/2017?download=csv -O "./日経平均株価_日足_2017.csv"; sleep 4; | N3: ="wget --user-agent Mozilla/4.0 http://k-db.com" & $B3 & "/4h/" & N$2 & "?download=csv -O ""./" & $A3 & "_" & $N$1 & "_" & C$2 & ".csv""; sleep 4;" -> wget --user-agent Mozilla/4.0 http://k-db.com/indices/I101/4h/2007?download=csv -O "./日経平均株価_前場後場_2007.csv"; sleep 4; | O3: ="wget --user-agent Mozilla/4.0 http://k-db.com" & $B3 & "/4h/" & O$2 & "?download=csv -O ""./" & $A3 & "_" & $N$1 & "_" & D$2 & ".csv""; sleep 4;" -> wget --user-agent Mozilla/4.0 http://k-db.com/indices/I101/4h/2008?download=csv -O "./日経平均株価_前場後場_2008.csv"; sleep 4; | P3: ="wget --user-agent Mozilla/4.0 http://k-db.com" & $B3 & "/4h/" & P$2 & "?download=csv -O ""./" & $A3 & "_" & $N$1 & "_" & E$2 & ".csv""; sleep 4;" -> wget --user-agent Mozilla/4.0 http://k-db.com/indices/I101/4h/2009?download=csv -O "./日経平均株価_前場後場_2009.csv"; sleep 4; | Q3: ="wget --user-agent Mozilla/4.0 http://k-db.com" & $B3 & "/4h/" & Q$2 & "?download=csv -O ""./" & $A3 & "_" & $N$1 & "_" & F$2 & ".csv""; sleep 4;" -> wget --user-agent Mozilla/4.0 http://k-db.com/indices/I101/4h/2010?download=csv -O "./日経平均株価_前場後場_2010.csv"; sleep 4; | R3: ="wget --user-agent Mozilla/4.0 http://k-db.com" & $B3 & "/4h/" & R$2 & "?download=csv -O ""./" & $A3 & "_" & $N$1 & "_" & G$2 & ".csv""; sleep 4;" -> wget --user-agent Mozilla/4.0 http://k-db.com/indices/I101/4h/2011?download=csv -O "./日経平均株価_前場後場_2011.csv"; sleep 4; | S3: ="wget --user-agent Mozilla/4.0 http://k-db.com" & $B3 & "/4h/" & S$2 & "?download=csv -O ""./" & $A3 & "_" & $N$1 & "_" & H$2 & ".csv""; sleep 4;" -> wget --user-agent Mozilla/4.0 http://k-db.com/indices/I101/4h/2012?download=csv -O "./日経平均株価_前場後場_2012.csv"; sleep 4; | T3: ="wget --user-agent Mozilla/4.0 http://k-db.com" & $B3 & "/4h/" & T$2 & "?download=csv -O ""./" & $A3 & "_" & $N$1 & "_" & I$2 & ".csv""; sleep 4;" -> wget --user-agent Mozilla/4.0 http://k-db.com/indices/I101/4h/2013?download=csv -O "./日経平均株価_前場後場_2013.csv"; sleep 4; | U3: ="wget --user-agent Mozilla/4.0 http://k-db.com" & $B3 & "/4h/" & U$2 & "?download=csv -O ""./" & $A3 & "_" & $N$1 & "_" & J$2 & ".csv""; sleep 4;" -> wget --user-agent Mozilla/4.0 http://k-db.com/indices/I101/4h/2014?download=csv -O "./日経平均株価_前場後場_2014.csv"; sleep 4; | ... X3: ="wget --user-agent Mozilla/4.0 http://k-db.com" & $B3 & "/4h/" & X$2 & "?download=csv -O ""./" & $A3 & "_" & $N$1 & "_" & M$2 & ".csv""; sleep 4;" -> wget --user-agent Mozilla/4.0 http://k-db.com/indices/I101/4h/2017?download=csv -O "./日経平均株価_前場後場_2017.csv"; sleep 4;
A4: TOPIX | B4: /indices/I102 | C4: ="wget --user-agent Mozilla/4.0 http://k-db.com" & $B4 & "/1d/" & C$2 & "?download=csv -O ""./" & $A4 & "_" & $C$1 & "_" & C$2 & ".csv""; sleep 4;" -> wget --user-agent Mozilla/4.0 http://k-db.com/indices/I102/1d/2007?download=csv -O "./TOPIX_日足_2007.csv"; sleep 4; | D4: ="wget --user-agent Mozilla/4.0 http://k-db.com" & $B4 & "/1d/" & D$2 & "?download=csv -O ""./" & $A4 & "_" & $C$1 & "_" & D$2 & ".csv""; sleep 4;" -> wget --user-agent Mozilla/4.0 http://k-db.com/indices/I102/1d/2008?download=csv -O "./TOPIX_日足_2008.csv"; sleep 4; | E4: ="wget --user-agent Mozilla/4.0 http://k-db.com" & $B4 & "/1d/" & E$2 & "?download=csv -O ""./" & $A4 & "_" & $C$1 & "_" & E$2 & ".csv""; sleep 4;" -> wget --user-agent Mozilla/4.0 http://k-db.com/indices/I102/1d/2009?download=csv -O "./TOPIX_日足_2009.csv"; sleep 4; | F4: ="wget --user-agent Mozilla/4.0 http://k-db.com" & $B4 & "/1d/" & F$2 & "?download=csv -O ""./" & $A4 & "_" & $C$1 & "_" & F$2 & ".csv""; sleep 4;" -> wget --user-agent Mozilla/4.0 http://k-db.com/indices/I102/1d/2010?download=csv -O "./TOPIX_日足_2010.csv"; sleep 4; | G4: ="wget --user-agent Mozilla/4.0 http://k-db.com" & $B4 & "/1d/" & G$2 & "?download=csv -O ""./" & $A4 & "_" & $C$1 & "_" & G$2 & ".csv""; sleep 4;" -> wget --user-agent Mozilla/4.0 http://k-db.com/indices/I102/1d/2011?download=csv -O "./TOPIX_日足_2011.csv"; sleep 4; | H4: ="wget --user-agent Mozilla/4.0 http://k-db.com" & $B4 & "/1d/" & H$2 & "?download=csv -O ""./" & $A4 & "_" & $C$1 & "_" & H$2 & ".csv""; sleep 4;" -> wget --user-agent Mozilla/4.0 http://k-db.com/indices/I102/1d/2012?download=csv -O "./TOPIX_日足_2012.csv"; sleep 4; | I4: ="wget --user-agent Mozilla/4.0 http://k-db.com" & $B4 & "/1d/" & I$2 & "?download=csv -O ""./" & $A4 & "_" & $C$1 & "_" & I$2 & ".csv""; sleep 4;" -> wget --user-agent Mozilla/4.0 http://k-db.com/indices/I102/1d/2013?download=csv -O "./TOPIX_日足_2013.csv"; sleep 4; | J4: ="wget --user-agent Mozilla/4.0 http://k-db.com" & $B4 & "/1d/" & J$2 & "?download=csv -O ""./" & $A4 & "_" & $C$1 & "_" & J$2 & ".csv""; sleep 4;" -> wget --user-agent Mozilla/4.0 http://k-db.com/indices/I102/1d/2014?download=csv -O "./TOPIX_日足_2014.csv"; sleep 4; | ... M4: ="wget --user-agent Mozilla/4.0 http://k-db.com" & $B4 & "/1d/" & M$2 & "?download=csv -O ""./" & $A4 & "_" & $C$1 & "_" & M$2 & ".csv""; sleep 4;" -> wget --user-agent Mozilla/4.0 http://k-db.com/indices/I102/1d/2017?download=csv -O "./TOPIX_日足_2017.csv"; sleep 4; | N4: ="wget --user-agent Mozilla/4.0 http://k-db.com" & $B4 & "/4h/" & N$2 & "?download=csv -O ""./" & $A4 & "_" & $N$1 & "_" & C$2 & ".csv""; sleep 4;" -> wget --user-agent Mozilla/4.0 http://k-db.com/indices/I102/4h/2007?download=csv -O "./TOPIX_前場後場_2007.csv"; sleep 4; | O4: ="wget --user-agent Mozilla/4.0 http://k-db.com" & $B4 & "/4h/" & O$2 & "?download=csv -O ""./" & $A4 & "_" & $N$1 & "_" & D$2 & ".csv""; sleep 4;" -> wget --user-agent Mozilla/4.0 http://k-db.com/indices/I102/4h/2008?download=csv -O "./TOPIX_前場後場_2008.csv"; sleep 4; | P4: ="wget --user-agent Mozilla/4.0 http://k-db.com" & $B4 & "/4h/" & P$2 & "?download=csv -O ""./" & $A4 & "_" & $N$1 & "_" & E$2 & ".csv""; sleep 4;" -> wget --user-agent Mozilla/4.0 http://k-db.com/indices/I102/4h/2009?download=csv -O "./TOPIX_前場後場_2009.csv"; sleep 4; | Q4: ="wget --user-agent Mozilla/4.0 http://k-db.com" & $B4 & "/4h/" & Q$2 & "?download=csv -O ""./" & $A4 & "_" & $N$1 & "_" & F$2 & ".csv""; sleep 4;" -> wget --user-agent Mozilla/4.0 http://k-db.com/indices/I102/4h/2010?download=csv -O "./TOPIX_前場後場_2010.csv"; sleep 4; | R4: ="wget --user-agent Mozilla/4.0 http://k-db.com" & $B4 & "/4h/" & R$2 & "?download=csv -O ""./" & $A4 & "_" & $N$1 & "_" & G$2 & ".csv""; sleep 4;" -> wget --user-agent Mozilla/4.0 http://k-db.com/indices/I102/4h/2011?download=csv -O "./TOPIX_前場後場_2011.csv"; sleep 4; | S4: ="wget --user-agent Mozilla/4.0 http://k-db.com" & $B4 & "/4h/" & S$2 & "?download=csv -O ""./" & $A4 & "_" & $N$1 & "_" & H$2 & ".csv""; sleep 4;" -> wget --user-agent Mozilla/4.0 http://k-db.com/indices/I102/4h/2012?download=csv -O "./TOPIX_前場後場_2012.csv"; sleep 4; | T4: ="wget --user-agent Mozilla/4.0 http://k-db.com" & $B4 & "/4h/" & T$2 & "?download=csv -O ""./" & $A4 & "_" & $N$1 & "_" & I$2 & ".csv""; sleep 4;" -> wget --user-agent Mozilla/4.0 http://k-db.com/indices/I102/4h/2013?download=csv -O "./TOPIX_前場後場_2013.csv"; sleep 4; | U4: ="wget --user-agent Mozilla/4.0 http://k-db.com" & $B4 & "/4h/" & U$2 & "?download=csv -O ""./" & $A4 & "_" & $N$1 & "_" & J$2 & ".csv""; sleep 4;" -> wget --user-agent Mozilla/4.0 http://k-db.com/indices/I102/4h/2014?download=csv -O "./TOPIX_前場後場_2014.csv"; sleep 4; | ... X4: ="wget --user-agent Mozilla/4.0 http://k-db.com" & $B4 & "/4h/" & X$2 & "?download=csv -O ""./" & $A4 & "_" & $N$1 & "_" & M$2 & ".csv""; sleep 4;" -> wget --user-agent Mozilla/4.0 http://k-db.com/indices/I102/4h/2017?download=csv -O "./TOPIX_前場後場_2017.csv"; sleep 4;
A5: JPX日経インデックス400 | B5: /indices/I103 | C5: ="wget --user-agent Mozilla/4.0 http://k-db.com" & $B5 & "/1d/" & C$2 & "?download=csv -O ""./" & $A5 & "_" & $C$1 & "_" & C$2 & ".csv""; sleep 4;" -> wget --user-agent Mozilla/4.0 http://k-db.com/indices/I103/1d/2007?download=csv -O "./JPX日経インデックス400_日足_2007.csv"; sleep 4; | D5: ="wget --user-agent Mozilla/4.0 http://k-db.com" & $B5 & "/1d/" & D$2 & "?download=csv -O ""./" & $A5 & "_" & $C$1 & "_" & D$2 & ".csv""; sleep 4;" -> wget --user-agent Mozilla/4.0 http://k-db.com/indices/I103/1d/2008?download=csv -O "./JPX日経インデックス400_日足_2008.csv"; sleep 4; | E5: ="wget --user-agent Mozilla/4.0 http://k-db.com" & $B5 & "/1d/" & E$2 & "?download=csv -O ""./" & $A5 & "_" & $C$1 & "_" & E$2 & ".csv""; sleep 4;" -> wget --user-agent Mozilla/4.0 http://k-db.com/indices/I103/1d/2009?download=csv -O "./JPX日経インデックス400_日足_2009.csv"; sleep 4; | F5: ="wget --user-agent Mozilla/4.0 http://k-db.com" & $B5 & "/1d/" & F$2 & "?download=csv -O ""./" & $A5 & "_" & $C$1 & "_" & F$2 & ".csv""; sleep 4;" -> wget --user-agent Mozilla/4.0 http://k-db.com/indices/I103/1d/2010?download=csv -O "./JPX日経インデックス400_日足_2010.csv"; sleep 4; | G5: ="wget --user-agent Mozilla/4.0 http://k-db.com" & $B5 & "/1d/" & G$2 & "?download=csv -O ""./" & $A5 & "_" & $C$1 & "_" & G$2 & ".csv""; sleep 4;" -> wget --user-agent Mozilla/4.0 http://k-db.com/indices/I103/1d/2011?download=csv -O "./JPX日経インデックス400_日足_2011.csv"; sleep 4; | H5: ="wget --user-agent Mozilla/4.0 http://k-db.com" & $B5 & "/1d/" & H$2 & "?download=csv -O ""./" & $A5 & "_" & $C$1 & "_" & H$2 & ".csv""; sleep 4;" -> wget --user-agent Mozilla/4.0 http://k-db.com/indices/I103/1d/2012?download=csv -O "./JPX日経インデックス400_日足_2012.csv"; sleep 4; | I5: ="wget --user-agent Mozilla/4.0 http://k-db.com" & $B5 & "/1d/" & I$2 & "?download=csv -O ""./" & $A5 & "_" & $C$1 & "_" & I$2 & ".csv""; sleep 4;" -> wget --user-agent Mozilla/4.0 http://k-db.com/indices/I103/1d/2013?download=csv -O "./JPX日経インデックス400_日足_2013.csv"; sleep 4; | J5: ="wget --user-agent Mozilla/4.0 http://k-db.com" & $B5 & "/1d/" & J$2 & "?download=csv -O ""./" & $A5 & "_" & $C$1 & "_" & J$2 & ".csv""; sleep 4;" -> wget --user-agent Mozilla/4.0 http://k-db.com/indices/I103/1d/2014?download=csv -O "./JPX日経インデックス400_日足_2014.csv"; sleep 4; | ... M5: ="wget --user-agent Mozilla/4.0 http://k-db.com" & $B5 & "/1d/" & M$2 & "?download=csv -O ""./" & $A5 & "_" & $C$1 & "_" & M$2 & ".csv""; sleep 4;" -> wget --user-agent Mozilla/4.0 http://k-db.com/indices/I103/1d/2017?download=csv -O "./JPX日経インデックス400_日足_2017.csv"; sleep 4; | N5: ="wget --user-agent Mozilla/4.0 http://k-db.com" & $B5 & "/4h/" & N$2 & "?download=csv -O ""./" & $A5 & "_" & $N$1 & "_" & C$2 & ".csv""; sleep 4;" -> wget --user-agent Mozilla/4.0 http://k-db.com/indices/I103/4h/2007?download=csv -O "./JPX日経インデックス400_前場後場_2007.csv"; sleep 4; | O5: ="wget --user-agent Mozilla/4.0 http://k-db.com" & $B5 & "/4h/" & O$2 & "?download=csv -O ""./" & $A5 & "_" & $N$1 & "_" & D$2 & ".csv""; sleep 4;" -> wget --user-agent Mozilla/4.0 http://k-db.com/indices/I103/4h/2008?download=csv -O "./JPX日経インデックス400_前場後場_2008.csv"; sleep 4; | P5: ="wget --user-agent Mozilla/4.0 http://k-db.com" & $B5 & "/4h/" & P$2 & "?download=csv -O ""./" & $A5 & "_" & $N$1 & "_" & E$2 & ".csv""; sleep 4;" -> wget --user-agent Mozilla/4.0 http://k-db.com/indices/I103/4h/2009?download=csv -O "./JPX日経インデックス400_前場後場_2009.csv"; sleep 4; | Q5: ="wget --user-agent Mozilla/4.0 http://k-db.com" & $B5 & "/4h/" & Q$2 & "?download=csv -O ""./" & $A5 & "_" & $N$1 & "_" & F$2 & ".csv""; sleep 4;" -> wget --user-agent Mozilla/4.0 http://k-db.com/indices/I103/4h/2010?download=csv -O "./JPX日経インデックス400_前場後場_2010.csv"; sleep 4; | R5: ="wget --user-agent Mozilla/4.0 http://k-db.com" & $B5 & "/4h/" & R$2 & "?download=csv -O ""./" & $A5 & "_" & $N$1 & "_" & G$2 & ".csv""; sleep 4;" -> wget --user-agent Mozilla/4.0 http://k-db.com/indices/I103/4h/2011?download=csv -O "./JPX日経インデックス400_前場後場_2011.csv"; sleep 4; | S5: ="wget --user-agent Mozilla/4.0 http://k-db.com" & $B5 & "/4h/" & S$2 & "?download=csv -O ""./" & $A5 & "_" & $N$1 & "_" & H$2 & ".csv""; sleep 4;" -> wget --user-agent Mozilla/4.0 http://k-db.com/indices/I103/4h/2012?download=csv -O "./JPX日経インデックス400_前場後場_2012.csv"; sleep 4; | T5: ="wget --user-agent Mozilla/4.0 http://k-db.com" & $B5 & "/4h/" & T$2 & "?download=csv -O ""./" & $A5 & "_" & $N$1 & "_" & I$2 & ".csv""; sleep 4;" -> wget --user-agent Mozilla/4.0 http://k-db.com/indices/I103/4h/2013?download=csv -O "./JPX日経インデックス400_前場後場_2013.csv"; sleep 4; | U5: ="wget --user-agent Mozilla/4.0 http://k-db.com" & $B5 & "/4h/" & U$2 & "?download=csv -O ""./" & $A5 & "_" & $N$1 & "_" & J$2 & ".csv""; sleep 4;" -> wget --user-agent Mozilla/4.0 http://k-db.com/indices/I103/4h/2014?download=csv -O "./JPX日経インデックス400_前場後場_2014.csv"; sleep 4; | ... X5: ="wget --user-agent Mozilla/4.0 http://k-db.com" & $B5 & "/4h/" & X$2 & "?download=csv -O ""./" & $A5 & "_" & $N$1 & "_" & M$2 & ".csv""; sleep 4;" -> wget --user-agent Mozilla/4.0 http://k-db.com/indices/I103/4h/2017?download=csv -O "./JPX日経インデックス400_前場後場_2017.csv"; sleep 4;
A6: 東証2部株価指数 | B6: /indices/I104 | C6: ="wget --user-agent Mozilla/4.0 http://k-db.com" & $B6 & "/1d/" & C$2 & "?download=csv -O ""./" & $A6 & "_" & $C$1 & "_" & C$2 & ".csv""; sleep 4;" -> wget --user-agent Mozilla/4.0 http://k-db.com/indices/I104/1d/2007?download=csv -O "./東証2部株価指数_日足_2007.csv"; sleep 4; | D6: ="wget --user-agent Mozilla/4.0 http://k-db.com" & $B6 & "/1d/" & D$2 & "?download=csv -O ""./" & $A6 & "_" & $C$1 & "_" & D$2 & ".csv""; sleep 4;" -> wget --user-agent Mozilla/4.0 http://k-db.com/indices/I104/1d/2008?download=csv -O "./東証2部株価指数_日足_2008.csv"; sleep 4; | E6: ="wget --user-agent Mozilla/4.0 http://k-db.com" & $B6 & "/1d/" & E$2 & "?download=csv -O ""./" & $A6 & "_" & $C$1 & "_" & E$2 & ".csv""; sleep 4;" -> wget --user-agent Mozilla/4.0 http://k-db.com/indices/I104/1d/2009?download=csv -O "./東証2部株価指数_日足_2009.csv"; sleep 4; | F6: ="wget --user-agent Mozilla/4.0 http://k-db.com" & $B6 & "/1d/" & F$2 & "?download=csv -O ""./" & $A6 & "_" & $C$1 & "_" & F$2 & ".csv""; sleep 4;" -> wget --user-agent Mozilla/4.0 http://k-db.com/indices/I104/1d/2010?download=csv -O "./東証2部株価指数_日足_2010.csv"; sleep 4; | G6: ="wget --user-agent Mozilla/4.0 http://k-db.com" & $B6 & "/1d/" & G$2 & "?download=csv -O ""./" & $A6 & "_" & $C$1 & "_" & G$2 & ".csv""; sleep 4;" -> wget --user-agent Mozilla/4.0 http://k-db.com/indices/I104/1d/2011?download=csv -O "./東証2部株価指数_日足_2011.csv"; sleep 4; | H6: ="wget --user-agent Mozilla/4.0 http://k-db.com" & $B6 & "/1d/" & H$2 & "?download=csv -O ""./" & $A6 & "_" & $C$1 & "_" & H$2 & ".csv""; sleep 4;" -> wget --user-agent Mozilla/4.0 http://k-db.com/indices/I104/1d/2012?download=csv -O "./東証2部株価指数_日足_2012.csv"; sleep 4; | I6: ="wget --user-agent Mozilla/4.0 http://k-db.com" & $B6 & "/1d/" & I$2 & "?download=csv -O ""./" & $A6 & "_" & $C$1 & "_" & I$2 & ".csv""; sleep 4;" -> wget --user-agent Mozilla/4.0 http://k-db.com/indices/I104/1d/2013?download=csv -O "./東証2部株価指数_日足_2013.csv"; sleep 4; | J6: ="wget --user-agent Mozilla/4.0 http://k-db.com" & $B6 & "/1d/" & J$2 & "?download=csv -O ""./" & $A6 & "_" & $C$1 & "_" & J$2 & ".csv""; sleep 4;" -> wget --user-agent Mozilla/4.0 http://k-db.com/indices/I104/1d/2014?download=csv -O "./東証2部株価指数_日足_2014.csv"; sleep 4; | ... M6: ="wget --user-agent Mozilla/4.0 http://k-db.com" & $B6 & "/1d/" & M$2 & "?download=csv -O ""./" & $A6 & "_" & $C$1 & "_" & M$2 & ".csv""; sleep 4;" -> wget --user-agent Mozilla/4.0 http://k-db.com/indices/I104/1d/2017?download=csv -O "./東証2部株価指数_日足_2017.csv"; sleep 4; | N6: ="wget --user-agent Mozilla/4.0 http://k-db.com" & $B6 & "/4h/" & N$2 & "?download=csv -O ""./" & $A6 & "_" & $N$1 & "_" & C$2 & ".csv""; sleep 4;" -> wget --user-agent Mozilla/4.0 http://k-db.com/indices/I104/4h/2007?download=csv -O "./東証2部株価指数_前場後場_2007.csv"; sleep 4; | O6: ="wget --user-agent Mozilla/4.0 http://k-db.com" & $B6 & "/4h/" & O$2 & "?download=csv -O ""./" & $A6 & "_" & $N$1 & "_" & D$2 & ".csv""; sleep 4;" -> wget --user-agent Mozilla/4.0 http://k-db.com/indices/I104/4h/2008?download=csv -O "./東証2部株価指数_前場後場_2008.csv"; sleep 4; | P6: ="wget --user-agent Mozilla/4.0 http://k-db.com" & $B6 & "/4h/" & P$2 & "?download=csv -O ""./" & $A6 & "_" & $N$1 & "_" & E$2 & ".csv""; sleep 4;" -> wget --user-agent Mozilla/4.0 http://k-db.com/indices/I104/4h/2009?download=csv -O "./東証2部株価指数_前場後場_2009.csv"; sleep 4; | Q6: ="wget --user-agent Mozilla/4.0 http://k-db.com" & $B6 & "/4h/" & Q$2 & "?download=csv -O ""./" & $A6 & "_" & $N$1 & "_" & F$2 & ".csv""; sleep 4;" -> wget --user-agent Mozilla/4.0 http://k-db.com/indices/I104/4h/2010?download=csv -O "./東証2部株価指数_前場後場_2010.csv"; sleep 4; | R6: ="wget --user-agent Mozilla/4.0 http://k-db.com" & $B6 & "/4h/" & R$2 & "?download=csv -O ""./" & $A6 & "_" & $N$1 & "_" & G$2 & ".csv""; sleep 4;" -> wget --user-agent Mozilla/4.0 http://k-db.com/indices/I104/4h/2011?download=csv -O "./東証2部株価指数_前場後場_2011.csv"; sleep 4; | S6: ="wget --user-agent Mozilla/4.0 http://k-db.com" & $B6 & "/4h/" & S$2 & "?download=csv -O ""./" & $A6 & "_" & $N$1 & "_" & H$2 & ".csv""; sleep 4;" -> wget --user-agent Mozilla/4.0 http://k-db.com/indices/I104/4h/2012?download=csv -O "./東証2部株価指数_前場後場_2012.csv"; sleep 4; | T6: ="wget --user-agent Mozilla/4.0 http://k-db.com" & $B6 & "/4h/" & T$2 & "?download=csv -O ""./" & $A6 & "_" & $N$1 & "_" & I$2 & ".csv""; sleep 4;" -> wget --user-agent Mozilla/4.0 http://k-db.com/indices/I104/4h/2013?download=csv -O "./東証2部株価指数_前場後場_2013.csv"; sleep 4; | U6: ="wget --user-agent Mozilla/4.0 http://k-db.com" & $B6 & "/4h/" & U$2 & "?download=csv -O ""./" & $A6 & "_" & $N$1 & "_" & J$2 & ".csv""; sleep 4;" -> wget --user-agent Mozilla/4.0 http://k-db.com/indices/I104/4h/2014?download=csv -O "./東証2部株価指数_前場後場_2014.csv"; sleep 4; | ... X6: ="wget --user-agent Mozilla/4.0 http://k-db.com" & $B6 & "/4h/" & X$2 & "?download=csv -O ""./" & $A6 & "_" & $N$1 & "_" & M$2 & ".csv""; sleep 4;" -> wget --user-agent Mozilla/4.0 http://k-db.com/indices/I104/4h/2017?download=csv -O "./東証2部株価指数_前場後場_2017.csv"; sleep 4;
A7: 東証マザーズ指数 | B7: /indices/I105 | C7: ="wget --user-agent Mozilla/4.0 http://k-db.com" & $B7 & "/1d/" & C$2 & "?download=csv -O ""./" & $A7 & "_" & $C$1 & "_" & C$2 & ".csv""; sleep 4;" -> wget --user-agent Mozilla/4.0 http://k-db.com/indices/I105/1d/2007?download=csv -O "./東証マザーズ指数_日足_2007.csv"; sleep 4; | D7: ="wget --user-agent Mozilla/4.0 http://k-db.com" & $B7 & "/1d/" & D$2 & "?download=csv -O ""./" & $A7 & "_" & $C$1 & "_" & D$2 & ".csv""; sleep 4;" -> wget --user-agent Mozilla/4.0 http://k-db.com/indices/I105/1d/2008?download=csv -O "./東証マザーズ指数_日足_2008.csv"; sleep 4; | E7: ="wget --user-agent Mozilla/4.0 http://k-db.com" & $B7 & "/1d/" & E$2 & "?download=csv -O ""./" & $A7 & "_" & $C$1 & "_" & E$2 & ".csv""; sleep 4;" -> wget --user-agent Mozilla/4.0 http://k-db.com/indices/I105/1d/2009?download=csv -O "./東証マザーズ指数_日足_2009.csv"; sleep 4; | F7: ="wget --user-agent Mozilla/4.0 http://k-db.com" & $B7 & "/1d/" & F$2 & "?download=csv -O ""./" & $A7 & "_" & $C$1 & "_" & F$2 & ".csv""; sleep 4;" -> wget --user-agent Mozilla/4.0 http://k-db.com/indices/I105/1d/2010?download=csv -O "./東証マザーズ指数_日足_2010.csv"; sleep 4; | G7: ="wget --user-agent Mozilla/4.0 http://k-db.com" & $B7 & "/1d/" & G$2 & "?download=csv -O ""./" & $A7 & "_" & $C$1 & "_" & G$2 & ".csv""; sleep 4;" -> wget --user-agent Mozilla/4.0 http://k-db.com/indices/I105/1d/2011?download=csv -O "./東証マザーズ指数_日足_2011.csv"; sleep 4; | H7: ="wget --user-agent Mozilla/4.0 http://k-db.com" & $B7 & "/1d/" & H$2 & "?download=csv -O ""./" & $A7 & "_" & $C$1 & "_" & H$2 & ".csv""; sleep 4;" -> wget --user-agent Mozilla/4.0 http://k-db.com/indices/I105/1d/2012?download=csv -O "./東証マザーズ指数_日足_2012.csv"; sleep 4; | I7: ="wget --user-agent Mozilla/4.0 http://k-db.com" & $B7 & "/1d/" & I$2 & "?download=csv -O ""./" & $A7 & "_" & $C$1 & "_" & I$2 & ".csv""; sleep 4;" -> wget --user-agent Mozilla/4.0 http://k-db.com/indices/I105/1d/2013?download=csv -O "./東証マザーズ指数_日足_2013.csv"; sleep 4; | J7: ="wget --user-agent Mozilla/4.0 http://k-db.com" & $B7 & "/1d/" & J$2 & "?download=csv -O ""./" & $A7 & "_" & $C$1 & "_" & J$2 & ".csv""; sleep 4;" -> wget --user-agent Mozilla/4.0 http://k-db.com/indices/I105/1d/2014?download=csv -O "./東証マザーズ指数_日足_2014.csv"; sleep 4; | ... M7: ="wget --user-agent Mozilla/4.0 http://k-db.com" & $B7 & "/1d/" & M$2 & "?download=csv -O ""./" & $A7 & "_" & $C$1 & "_" & M$2 & ".csv""; sleep 4;" -> wget --user-agent Mozilla/4.0 http://k-db.com/indices/I105/1d/2017?download=csv -O "./東証マザーズ指数_日足_2017.csv"; sleep 4; | N7: ="wget --user-agent Mozilla/4.0 http://k-db.com" & $B7 & "/4h/" & N$2 & "?download=csv -O ""./" & $A7 & "_" & $N$1 & "_" & C$2 & ".csv""; sleep 4;" -> wget --user-agent Mozilla/4.0 http://k-db.com/indices/I105/4h/2007?download=csv -O "./東証マザーズ指数_前場後場_2007.csv"; sleep 4; | O7: ="wget --user-agent Mozilla/4.0 http://k-db.com" & $B7 & "/4h/" & O$2 & "?download=csv -O ""./" & $A7 & "_" & $N$1 & "_" & D$2 & ".csv""; sleep 4;" -> wget --user-agent Mozilla/4.0 http://k-db.com/indices/I105/4h/2008?download=csv -O "./東証マザーズ指数_前場後場_2008.csv"; sleep 4; | P7: ="wget --user-agent Mozilla/4.0 http://k-db.com" & $B7 & "/4h/" & P$2 & "?download=csv -O ""./" & $A7 & "_" & $N$1 & "_" & E$2 & ".csv""; sleep 4;" -> wget --user-agent Mozilla/4.0 http://k-db.com/indices/I105/4h/2009?download=csv -O "./東証マザーズ指数_前場後場_2009.csv"; sleep 4; | Q7: ="wget --user-agent Mozilla/4.0 http://k-db.com" & $B7 & "/4h/" & Q$2 & "?download=csv -O ""./" & $A7 & "_" & $N$1 & "_" & F$2 & ".csv""; sleep 4;" -> wget --user-agent Mozilla/4.0 http://k-db.com/indices/I105/4h/2010?download=csv -O "./東証マザーズ指数_前場後場_2010.csv"; sleep 4; | R7: ="wget --user-agent Mozilla/4.0 http://k-db.com" & $B7 & "/4h/" & R$2 & "?download=csv -O ""./" & $A7 & "_" & $N$1 & "_" & G$2 & ".csv""; sleep 4;" -> wget --user-agent Mozilla/4.0 http://k-db.com/indices/I105/4h/2011?download=csv -O "./東証マザーズ指数_前場後場_2011.csv"; sleep 4; | S7: ="wget --user-agent Mozilla/4.0 http://k-db.com" & $B7 & "/4h/" & S$2 & "?download=csv -O ""./" & $A7 & "_" & $N$1 & "_" & H$2 & ".csv""; sleep 4;" -> wget --user-agent Mozilla/4.0 http://k-db.com/indices/I105/4h/2012?download=csv -O "./東証マザーズ指数_前場後場_2012.csv"; sleep 4; | T7: ="wget --user-agent Mozilla/4.0 http://k-db.com" & $B7 & "/4h/" & T$2 & "?download=csv -O ""./" & $A7 & "_" & $N$1 & "_" & I$2 & ".csv""; sleep 4;" -> wget --user-agent Mozilla/4.0 http://k-db.com/indices/I105/4h/2013?download=csv -O "./東証マザーズ指数_前場後場_2013.csv"; sleep 4; | U7: ="wget --user-agent Mozilla/4.0 http://k-db.com" & $B7 & "/4h/" & U$2 & "?download=csv -O ""./" & $A7 & "_" & $N$1 & "_" & J$2 & ".csv""; sleep 4;" -> wget --user-agent Mozilla/4.0 http://k-db.com/indices/I105/4h/2014?download=csv -O "./東証マザーズ指数_前場後場_2014.csv"; sleep 4; | ... X7: ="wget --user-agent Mozilla/4.0 http://k-db.com" & $B7 & "/4h/" & X$2 & "?download=csv -O ""./" & $A7 & "_" & $N$1 & "_" & M$2 & ".csv""; sleep 4;" -> wget --user-agent Mozilla/4.0 http://k-db.com/indices/I105/4h/2017?download=csv -O "./東証マザーズ指数_前場後場_2017.csv"; sleep 4;
A8: TOPIX コア 30 | B8: /indices/I111 | C8: ="wget --user-agent Mozilla/4.0 http://k-db.com" & $B8 & "/1d/" & C$2 & "?download=csv -O ""./" & $A8 & "_" & $C$1 & "_" & C$2 & ".csv""; sleep 4;" -> wget --user-agent Mozilla/4.0 http://k-db.com/indices/I111/1d/2007?download=csv -O "./TOPIX コア 30_日足_2007.csv"; sleep 4; | D8: ="wget --user-agent Mozilla/4.0 http://k-db.com" & $B8 & "/1d/" & D$2 & "?download=csv -O ""./" & $A8 & "_" & $C$1 & "_" & D$2 & ".csv""; sleep 4;" -> wget --user-agent Mozilla/4.0 http://k-db.com/indices/I111/1d/2008?download=csv -O "./TOPIX コア 30_日足_2008.csv"; sleep 4; | E8: ="wget --user-agent Mozilla/4.0 http://k-db.com" & $B8 & "/1d/" & E$2 & "?download=csv -O ""./" & $A8 & "_" & $C$1 & "_" & E$2 & ".csv""; sleep 4;" -> wget --user-agent Mozilla/4.0 http://k-db.com/indices/I111/1d/2009?download=csv -O "./TOPIX コア 30_日足_2009.csv"; sleep 4; | F8: ="wget --user-agent Mozilla/4.0 http://k-db.com" & $B8 & "/1d/" & F$2 & "?download=csv -O ""./" & $A8 & "_" & $C$1 & "_" & F$2 & ".csv""; sleep 4;" -> wget --user-agent Mozilla/4.0 http://k-db.com/indices/I111/1d/2010?download=csv -O "./TOPIX コア 30_日足_2010.csv"; sleep 4; | G8: ="wget --user-agent Mozilla/4.0 http://k-db.com" & $B8 & "/1d/" & G$2 & "?download=csv -O ""./" & $A8 & "_" & $C$1 & "_" & G$2 & ".csv""; sleep 4;" -> wget --user-agent Mozilla/4.0 http://k-db.com/indices/I111/1d/2011?download=csv -O "./TOPIX コア 30_日足_2011.csv"; sleep 4; | H8: ="wget --user-agent Mozilla/4.0 http://k-db.com" & $B8 & "/1d/" & H$2 & "?download=csv -O ""./" & $A8 & "_" & $C$1 & "_" & H$2 & ".csv""; sleep 4;" -> wget --user-agent Mozilla/4.0 http://k-db.com/indices/I111/1d/2012?download=csv -O "./TOPIX コア 30_日足_2012.csv"; sleep 4; | I8: ="wget --user-agent Mozilla/4.0 http://k-db.com" & $B8 & "/1d/" & I$2 & "?download=csv -O ""./" & $A8 & "_" & $C$1 & "_" & I$2 & ".csv""; sleep 4;" -> wget --user-agent Mozilla/4.0 http://k-db.com/indices/I111/1d/2013?download=csv -O "./TOPIX コア 30_日足_2013.csv"; sleep 4; | J8: ="wget --user-agent Mozilla/4.0 http://k-db.com" & $B8 & "/1d/" & J$2 & "?download=csv -O ""./" & $A8 & "_" & $C$1 & "_" & J$2 & ".csv""; sleep 4;" -> wget --user-agent Mozilla/4.0 http://k-db.com/indices/I111/1d/2014?download=csv -O "./TOPIX コア 30_日足_2014.csv"; sleep 4; | ... M8: ="wget --user-agent Mozilla/4.0 http://k-db.com" & $B8 & "/1d/" & M$2 & "?download=csv -O ""./" & $A8 & "_" & $C$1 & "_" & M$2 & ".csv""; sleep 4;" -> wget --user-agent Mozilla/4.0 http://k-db.com/indices/I111/1d/2017?download=csv -O "./TOPIX コア 30_日足_2017.csv"; sleep 4; | N8: ="wget --user-agent Mozilla/4.0 http://k-db.com" & $B8 & "/4h/" & N$2 & "?download=csv -O ""./" & $A8 & "_" & $N$1 & "_" & C$2 & ".csv""; sleep 4;" -> wget --user-agent Mozilla/4.0 http://k-db.com/indices/I111/4h/2007?download=csv -O "./TOPIX コア 30_前場後場_2007.csv"; sleep 4; | O8: ="wget --user-agent Mozilla/4.0 http://k-db.com" & $B8 & "/4h/" & O$2 & "?download=csv -O ""./" & $A8 & "_" & $N$1 & "_" & D$2 & ".csv""; sleep 4;" -> wget --user-agent Mozilla/4.0 http://k-db.com/indices/I111/4h/2008?download=csv -O "./TOPIX コア 30_前場後場_2008.csv"; sleep 4; | P8: ="wget --user-agent Mozilla/4.0 http://k-db.com" & $B8 & "/4h/" & P$2 & "?download=csv -O ""./" & $A8 & "_" & $N$1 & "_" & E$2 & ".csv""; sleep 4;" -> wget --user-agent Mozilla/4.0 http://k-db.com/indices/I111/4h/2009?download=csv -O "./TOPIX コア 30_前場後場_2009.csv"; sleep 4; | Q8: ="wget --user-agent Mozilla/4.0 http://k-db.com" & $B8 & "/4h/" & Q$2 & "?download=csv -O ""./" & $A8 & "_" & $N$1 & "_" & F$2 & ".csv""; sleep 4;" -> wget --user-agent Mozilla/4.0 http://k-db.com/indices/I111/4h/2010?download=csv -O "./TOPIX コア 30_前場後場_2010.csv"; sleep 4; | R8: ="wget --user-agent Mozilla/4.0 http://k-db.com" & $B8 & "/4h/" & R$2 & "?download=csv -O ""./" & $A8 & "_" & $N$1 & "_" & G$2 & ".csv""; sleep 4;" -> wget --user-agent Mozilla/4.0 http://k-db.com/indices/I111/4h/2011?download=csv -O "./TOPIX コア 30_前場後場_2011.csv"; sleep 4; | S8: ="wget --user-agent Mozilla/4.0 http://k-db.com" & $B8 & "/4h/" & S$2 & "?download=csv -O ""./" & $A8 & "_" & $N$1 & "_" & H$2 & ".csv""; sleep 4;" -> wget --user-agent Mozilla/4.0 http://k-db.com/indices/I111/4h/2012?download=csv -O "./TOPIX コア 30_前場後場_2012.csv"; sleep 4; | T8: ="wget --user-agent Mozilla/4.0 http://k-db.com" & $B8 & "/4h/" & T$2 & "?download=csv -O ""./" & $A8 & "_" & $N$1 & "_" & I$2 & ".csv""; sleep 4;" -> wget --user-agent Mozilla/4.0 http://k-db.com/indices/I111/4h/2013?download=csv -O "./TOPIX コア 30_前場後場_2013.csv"; sleep 4; | U8: ="wget --user-agent Mozilla/4.0 http://k-db.com" & $B8 & "/4h/" & U$2 & "?download=csv -O ""./" & $A8 & "_" & $N$1 & "_" & J$2 & ".csv""; sleep 4;" -> wget --user-agent Mozilla/4.0 http://k-db.com/indices/I111/4h/2014?download=csv -O "./TOPIX コア 30_前場後場_2014.csv"; sleep 4; | ... X8: ="wget --user-agent Mozilla/4.0 http://k-db.com" & $B8 & "/4h/" & X$2 & "?download=csv -O ""./" & $A8 & "_" & $N$1 & "_" & M$2 & ".csv""; sleep 4;" -> wget --user-agent Mozilla/4.0 http://k-db.com/indices/I111/4h/2017?download=csv -O "./TOPIX コア 30_前場後場_2017.csv"; sleep 4;
A9: TOPIX ラージ 70 | B9: /indices/I112 | C9: ="wget --user-agent Mozilla/4.0 http://k-db.com" & $B9 & "/1d/" & C$2 & "?download=csv -O ""./" & $A9 & "_" & $C$1 & "_" & C$2 & ".csv""; sleep 4;" -> wget --user-agent Mozilla/4.0 http://k-db.com/indices/I112/1d/2007?download=csv -O "./TOPIX ラージ 70_日足_2007.csv"; sleep 4; | D9: ="wget --user-agent Mozilla/4.0 http://k-db.com" & $B9 & "/1d/" & D$2 & "?download=csv -O ""./" & $A9 & "_" & $C$1 & "_" & D$2 & ".csv""; sleep 4;" -> wget --user-agent Mozilla/4.0 http://k-db.com/indices/I112/1d/2008?download=csv -O "./TOPIX ラージ 70_日足_2008.csv"; sleep 4; | E9: ="wget --user-agent Mozilla/4.0 http://k-db.com" & $B9 & "/1d/" & E$2 & "?download=csv -O ""./" & $A9 & "_" & $C$1 & "_" & E$2 & ".csv""; sleep 4;" -> wget --user-agent Mozilla/4.0 http://k-db.com/indices/I112/1d/2009?download=csv -O "./TOPIX ラージ 70_日足_2009.csv"; sleep 4; | F9: ="wget --user-agent Mozilla/4.0 http://k-db.com" & $B9 & "/1d/" & F$2 & "?download=csv -O ""./" & $A9 & "_" & $C$1 & "_" & F$2 & ".csv""; sleep 4;" -> wget --user-agent Mozilla/4.0 http://k-db.com/indices/I112/1d/2010?download=csv -O "./TOPIX ラージ 70_日足_2010.csv"; sleep 4; | G9: ="wget --user-agent Mozilla/4.0 http://k-db.com" & $B9 & "/1d/" & G$2 & "?download=csv -O ""./" & $A9 & "_" & $C$1 & "_" & G$2 & ".csv""; sleep 4;" -> wget --user-agent Mozilla/4.0 http://k-db.com/indices/I112/1d/2011?download=csv -O "./TOPIX ラージ 70_日足_2011.csv"; sleep 4; | H9: ="wget --user-agent Mozilla/4.0 http://k-db.com" & $B9 & "/1d/" & H$2 & "?download=csv -O ""./" & $A9 & "_" & $C$1 & "_" & H$2 & ".csv""; sleep 4;" -> wget --user-agent Mozilla/4.0 http://k-db.com/indices/I112/1d/2012?download=csv -O "./TOPIX ラージ 70_日足_2012.csv"; sleep 4; | I9: ="wget --user-agent Mozilla/4.0 http://k-db.com" & $B9 & "/1d/" & I$2 & "?download=csv -O ""./" & $A9 & "_" & $C$1 & "_" & I$2 & ".csv""; sleep 4;" -> wget --user-agent Mozilla/4.0 http://k-db.com/indices/I112/1d/2013?download=csv -O "./TOPIX ラージ 70_日足_2013.csv"; sleep 4; | J9: ="wget --user-agent Mozilla/4.0 http://k-db.com" & $B9 & "/1d/" & J$2 & "?download=csv -O ""./" & $A9 & "_" & $C$1 & "_" & J$2 & ".csv""; sleep 4;" -> wget --user-agent Mozilla/4.0 http://k-db.com/indices/I112/1d/2014?download=csv -O "./TOPIX ラージ 70_日足_2014.csv"; sleep 4; | ... M9: ="wget --user-agent Mozilla/4.0 http://k-db.com" & $B9 & "/1d/" & M$2 & "?download=csv -O ""./" & $A9 & "_" & $C$1 & "_" & M$2 & ".csv""; sleep 4;" -> wget --user-agent Mozilla/4.0 http://k-db.com/indices/I112/1d/2017?download=csv -O "./TOPIX ラージ 70_日足_2017.csv"; sleep 4; | N9: ="wget --user-agent Mozilla/4.0 http://k-db.com" & $B9 & "/4h/" & N$2 & "?download=csv -O ""./" & $A9 & "_" & $N$1 & "_" & C$2 & ".csv""; sleep 4;" -> wget --user-agent Mozilla/4.0 http://k-db.com/indices/I112/4h/2007?download=csv -O "./TOPIX ラージ 70_前場後場_2007.csv"; sleep 4; | O9: ="wget --user-agent Mozilla/4.0 http://k-db.com" & $B9 & "/4h/" & O$2 & "?download=csv -O ""./" & $A9 & "_" & $N$1 & "_" & D$2 & ".csv""; sleep 4;" -> wget --user-agent Mozilla/4.0 http://k-db.com/indices/I112/4h/2008?download=csv -O "./TOPIX ラージ 70_前場後場_2008.csv"; sleep 4; | P9: ="wget --user-agent Mozilla/4.0 http://k-db.com" & $B9 & "/4h/" & P$2 & "?download=csv -O ""./" & $A9 & "_" & $N$1 & "_" & E$2 & ".csv""; sleep 4;" -> wget --user-agent Mozilla/4.0 http://k-db.com/indices/I112/4h/2009?download=csv -O "./TOPIX ラージ 70_前場後場_2009.csv"; sleep 4; | Q9: ="wget --user-agent Mozilla/4.0 http://k-db.com" & $B9 & "/4h/" & Q$2 & "?download=csv -O ""./" & $A9 & "_" & $N$1 & "_" & F$2 & ".csv""; sleep 4;" -> wget --user-agent Mozilla/4.0 http://k-db.com/indices/I112/4h/2010?download=csv -O "./TOPIX ラージ 70_前場後場_2010.csv"; sleep 4; | R9: ="wget --user-agent Mozilla/4.0 http://k-db.com" & $B9 & "/4h/" & R$2 & "?download=csv -O ""./" & $A9 & "_" & $N$1 & "_" & G$2 & ".csv""; sleep 4;" -> wget --user-agent Mozilla/4.0 http://k-db.com/indices/I112/4h/2011?download=csv -O "./TOPIX ラージ 70_前場後場_2011.csv"; sleep 4; | S9: ="wget --user-agent Mozilla/4.0 http://k-db.com" & $B9 & "/4h/" & S$2 & "?download=csv -O ""./" & $A9 & "_" & $N$1 & "_" & H$2 & ".csv""; sleep 4;" -> wget --user-agent Mozilla/4.0 http://k-db.com/indices/I112/4h/2012?download=csv -O "./TOPIX ラージ 70_前場後場_2012.csv"; sleep 4; | T9: ="wget --user-agent Mozilla/4.0 http://k-db.com" & $B9 & "/4h/" & T$2 & "?download=csv -O ""./" & $A9 & "_" & $N$1 & "_" & I$2 & ".csv""; sleep 4;" -> wget --user-agent Mozilla/4.0 http://k-db.com/indices/I112/4h/2013?download=csv -O "./TOPIX ラージ 70_前場後場_2013.csv"; sleep 4; | U9: ="wget --user-agent Mozilla/4.0 http://k-db.com" & $B9 & "/4h/" & U$2 & "?download=csv -O ""./" & $A9 & "_" & $N$1 & "_" & J$2 & ".csv""; sleep 4;" -> wget --user-agent Mozilla/4.0 http://k-db.com/indices/I112/4h/2014?download=csv -O "./TOPIX ラージ 70_前場後場_2014.csv"; sleep 4; | ... X9: ="wget --user-agent Mozilla/4.0 http://k-db.com" & $B9 & "/4h/" & X$2 & "?download=csv -O ""./" & $A9 & "_" & $N$1 & "_" & M$2 & ".csv""; sleep 4;" -> wget --user-agent Mozilla/4.0 http://k-db.com/indices/I112/4h/2017?download=csv -O "./TOPIX ラージ 70_前場後場_2017.csv"; sleep 4;
A10: TOPIX 100 | B10: /indices/I113 | C10: ="wget --user-agent Mozilla/4.0 http://k-db.com" & $B10 & "/1d/" & C$2 & "?download=csv -O ""./" & $A10 & "_" & $C$1 & "_" & C$2 & ".csv""; sleep 4;" -> wget --user-agent Mozilla/4.0 http://k-db.com/indices/I113/1d/2007?download=csv -O "./TOPIX 100_日足_2007.csv"; sleep 4; | D10: ="wget --user-agent Mozilla/4.0 http://k-db.com" & $B10 & "/1d/" & D$2 & "?download=csv -O ""./" & $A10 & "_" & $C$1 & "_" & D$2 & ".csv""; sleep 4;" -> wget --user-agent Mozilla/4.0 http://k-db.com/indices/I113/1d/2008?download=csv -O "./TOPIX 100_日足_2008.csv"; sleep 4; | E10: ="wget --user-agent Mozilla/4.0 http://k-db.com" & $B10 & "/1d/" & E$2 & "?download=csv -O ""./" & $A10 & "_" & $C$1 & "_" & E$2 & ".csv""; sleep 4;" -> wget --user-agent Mozilla/4.0 http://k-db.com/indices/I113/1d/2009?download=csv -O "./TOPIX 100_日足_2009.csv"; sleep 4; | F10: ="wget --user-agent Mozilla/4.0 http://k-db.com" & $B10 & "/1d/" & F$2 & "?download=csv -O ""./" & $A10 & "_" & $C$1 & "_" & F$2 & ".csv""; sleep 4;" -> wget --user-agent Mozilla/4.0 http://k-db.com/indices/I113/1d/2010?download=csv -O "./TOPIX 100_日足_2010.csv"; sleep 4; | G10: ="wget --user-agent Mozilla/4.0 http://k-db.com" & $B10 & "/1d/" & G$2 & "?download=csv -O ""./" & $A10 & "_" & $C$1 & "_" & G$2 & ".csv""; sleep 4;" -> wget --user-agent Mozilla/4.0 http://k-db.com/indices/I113/1d/2011?download=csv -O "./TOPIX 100_日足_2011.csv"; sleep 4; | H10: ="wget --user-agent Mozilla/4.0 http://k-db.com" & $B10 & "/1d/" & H$2 & "?download=csv -O ""./" & $A10 & "_" & $C$1 & "_" & H$2 & ".csv""; sleep 4;" -> wget --user-agent Mozilla/4.0 http://k-db.com/indices/I113/1d/2012?download=csv -O "./TOPIX 100_日足_2012.csv"; sleep 4; | I10: ="wget --user-agent Mozilla/4.0 http://k-db.com" & $B10 & "/1d/" & I$2 & "?download=csv -O ""./" & $A10 & "_" & $C$1 & "_" & I$2 & ".csv""; sleep 4;" -> wget --user-agent Mozilla/4.0 http://k-db.com/indices/I113/1d/2013?download=csv -O "./TOPIX 100_日足_2013.csv"; sleep 4; | J10: ="wget --user-agent Mozilla/4.0 http://k-db.com" & $B10 & "/1d/" & J$2 & "?download=csv -O ""./" & $A10 & "_" & $C$1 & "_" & J$2 & ".csv""; sleep 4;" -> wget --user-agent Mozilla/4.0 http://k-db.com/indices/I113/1d/2014?download=csv -O "./TOPIX 100_日足_2014.csv"; sleep 4; | ... M10: ="wget --user-agent Mozilla/4.0 http://k-db.com" & $B10 & "/1d/" & M$2 & "?download=csv -O ""./" & $A10 & "_" & $C$1 & "_" & M$2 & ".csv""; sleep 4;" -> wget --user-agent Mozilla/4.0 http://k-db.com/indices/I113/1d/2017?download=csv -O "./TOPIX 100_日足_2017.csv"; sleep 4; | N10: ="wget --user-agent Mozilla/4.0 http://k-db.com" & $B10 & "/4h/" & N$2 & "?download=csv -O ""./" & $A10 & "_" & $N$1 & "_" & C$2 & ".csv""; sleep 4;" -> wget --user-agent Mozilla/4.0 http://k-db.com/indices/I113/4h/2007?download=csv -O "./TOPIX 100_前場後場_2007.csv"; sleep 4; | O10: ="wget --user-agent Mozilla/4.0 http://k-db.com" & $B10 & "/4h/" & O$2 & "?download=csv -O ""./" & $A10 & "_" & $N$1 & "_" & D$2 & ".csv""; sleep 4;" -> wget --user-agent Mozilla/4.0 http://k-db.com/indices/I113/4h/2008?download=csv -O "./TOPIX 100_前場後場_2008.csv"; sleep 4; | P10: ="wget --user-agent Mozilla/4.0 http://k-db.com" & $B10 & "/4h/" & P$2 & "?download=csv -O ""./" & $A10 & "_" & $N$1 & "_" & E$2 & ".csv""; sleep 4;" -> wget --user-agent Mozilla/4.0 http://k-db.com/indices/I113/4h/2009?download=csv -O "./TOPIX 100_前場後場_2009.csv"; sleep 4; | Q10: ="wget --user-agent Mozilla/4.0 http://k-db.com" & $B10 & "/4h/" & Q$2 & "?download=csv -O ""./" & $A10 & "_" & $N$1 & "_" & F$2 & ".csv""; sleep 4;" -> wget --user-agent Mozilla/4.0 http://k-db.com/indices/I113/4h/2010?download=csv -O "./TOPIX 100_前場後場_2010.csv"; sleep 4; | R10: ="wget --user-agent Mozilla/4.0 http://k-db.com" & $B10 & "/4h/" & R$2 & "?download=csv -O ""./" & $A10 & "_" & $N$1 & "_" & G$2 & ".csv""; sleep 4;" -> wget --user-agent Mozilla/4.0 http://k-db.com/indices/I113/4h/2011?download=csv -O "./TOPIX 100_前場後場_2011.csv"; sleep 4; | S10: ="wget --user-agent Mozilla/4.0 http://k-db.com" & $B10 & "/4h/" & S$2 & "?download=csv -O ""./" & $A10 & "_" & $N$1 & "_" & H$2 & ".csv""; sleep 4;" -> wget --user-agent Mozilla/4.0 http://k-db.com/indices/I113/4h/2012?download=csv -O "./TOPIX 100_前場後場_2012.csv"; sleep 4; | T10: ="wget --user-agent Mozilla/4.0 http://k-db.com" & $B10 & "/4h/" & T$2 & "?download=csv -O ""./" & $A10 & "_" & $N$1 & "_" & I$2 & ".csv""; sleep 4;" -> wget --user-agent Mozilla/4.0 http://k-db.com/indices/I113/4h/2013?download=csv -O "./TOPIX 100_前場後場_2013.csv"; sleep 4; | U10: ="wget --user-agent Mozilla/4.0 http://k-db.com" & $B10 & "/4h/" & U$2 & "?download=csv -O ""./" & $A10 & "_" & $N$1 & "_" & J$2 & ".csv""; sleep 4;" -> wget --user-agent Mozilla/4.0 http://k-db.com/indices/I113/4h/2014?download=csv -O "./TOPIX 100_前場後場_2014.csv"; sleep 4; | ... X10: ="wget --user-agent Mozilla/4.0 http://k-db.com" & $B10 & "/4h/" & X$2 & "?download=csv -O ""./" & $A10 & "_" & $N$1 & "_" & M$2 & ".csv""; sleep 4;" -> wget --user-agent Mozilla/4.0 http://k-db.com/indices/I113/4h/2017?download=csv -O "./TOPIX 100_前場後場_2017.csv"; sleep 4;
A11: TOPIX ミッド 400 | B11: /indices/I114 | C11: ="wget --user-agent Mozilla/4.0 http://k-db.com" & $B11 & "/1d/" & C$2 & "?download=csv -O ""./" & $A11 & "_" & $C$1 & "_" & C$2 & ".csv""; sleep 4;" -> wget --user-agent Mozilla/4.0 http://k-db.com/indices/I114/1d/2007?download=csv -O "./TOPIX ミッド 400_日足_2007.csv"; sleep 4; | D11: ="wget --user-agent Mozilla/4.0 http://k-db.com" & $B11 & "/1d/" & D$2 & "?download=csv -O ""./" & $A11 & "_" & $C$1 & "_" & D$2 & ".csv""; sleep 4;" -> wget --user-agent Mozilla/4.0 http://k-db.com/indices/I114/1d/2008?download=csv -O "./TOPIX ミッド 400_日足_2008.csv"; sleep 4; | E11: ="wget --user-agent Mozilla/4.0 http://k-db.com" & $B11 & "/1d/" & E$2 & "?download=csv -O ""./" & $A11 & "_" & $C$1 & "_" & E$2 & ".csv""; sleep 4;" -> wget --user-agent Mozilla/4.0 http://k-db.com/indices/I114/1d/2009?download=csv -O "./TOPIX ミッド 400_日足_2009.csv"; sleep 4; | F11: ="wget --user-agent Mozilla/4.0 http://k-db.com" & $B11 & "/1d/" & F$2 & "?download=csv -O ""./" & $A11 & "_" & $C$1 & "_" & F$2 & ".csv""; sleep 4;" -> wget --user-agent Mozilla/4.0 http://k-db.com/indices/I114/1d/2010?download=csv -O "./TOPIX ミッド 400_日足_2010.csv"; sleep 4; | G11: ="wget --user-agent Mozilla/4.0 http://k-db.com" & $B11 & "/1d/" & G$2 & "?download=csv -O ""./" & $A11 & "_" & $C$1 & "_" & G$2 & ".csv""; sleep 4;" -> wget --user-agent Mozilla/4.0 http://k-db.com/indices/I114/1d/2011?download=csv -O "./TOPIX ミッド 400_日足_2011.csv"; sleep 4; | H11: ="wget --user-agent Mozilla/4.0 http://k-db.com" & $B11 & "/1d/" & H$2 & "?download=csv -O ""./" & $A11 & "_" & $C$1 & "_" & H$2 & ".csv""; sleep 4;" -> wget --user-agent Mozilla/4.0 http://k-db.com/indices/I114/1d/2012?download=csv -O "./TOPIX ミッド 400_日足_2012.csv"; sleep 4; | I11: ="wget --user-agent Mozilla/4.0 http://k-db.com" & $B11 & "/1d/" & I$2 & "?download=csv -O ""./" & $A11 & "_" & $C$1 & "_" & I$2 & ".csv""; sleep 4;" -> wget --user-agent Mozilla/4.0 http://k-db.com/indices/I114/1d/2013?download=csv -O "./TOPIX ミッド 400_日足_2013.csv"; sleep 4; | J11: ="wget --user-agent Mozilla/4.0 http://k-db.com" & $B11 & "/1d/" & J$2 & "?download=csv -O ""./" & $A11 & "_" & $C$1 & "_" & J$2 & ".csv""; sleep 4;" -> wget --user-agent Mozilla/4.0 http://k-db.com/indices/I114/1d/2014?download=csv -O "./TOPIX ミッド 400_日足_2014.csv"; sleep 4; | ... M11: ="wget --user-agent Mozilla/4.0 http://k-db.com" & $B11 & "/1d/" & M$2 & "?download=csv -O ""./" & $A11 & "_" & $C$1 & "_" & M$2 & ".csv""; sleep 4;" -> wget --user-agent Mozilla/4.0 http://k-db.com/indices/I114/1d/2017?download=csv -O "./TOPIX ミッド 400_日足_2017.csv"; sleep 4; | N11: ="wget --user-agent Mozilla/4.0 http://k-db.com" & $B11 & "/4h/" & N$2 & "?download=csv -O ""./" & $A11 & "_" & $N$1 & "_" & C$2 & ".csv""; sleep 4;" -> wget --user-agent Mozilla/4.0 http://k-db.com/indices/I114/4h/2007?download=csv -O "./TOPIX ミッド 400_前場後場_2007.csv"; sleep 4; | O11: ="wget --user-agent Mozilla/4.0 http://k-db.com" & $B11 & "/4h/" & O$2 & "?download=csv -O ""./" & $A11 & "_" & $N$1 & "_" & D$2 & ".csv""; sleep 4;" -> wget --user-agent Mozilla/4.0 http://k-db.com/indices/I114/4h/2008?download=csv -O "./TOPIX ミッド 400_前場後場_2008.csv"; sleep 4; | P11: ="wget --user-agent Mozilla/4.0 http://k-db.com" & $B11 & "/4h/" & P$2 & "?download=csv -O ""./" & $A11 & "_" & $N$1 & "_" & E$2 & ".csv""; sleep 4;" -> wget --user-agent Mozilla/4.0 http://k-db.com/indices/I114/4h/2009?download=csv -O "./TOPIX ミッド 400_前場後場_2009.csv"; sleep 4; | Q11: ="wget --user-agent Mozilla/4.0 http://k-db.com" & $B11 & "/4h/" & Q$2 & "?download=csv -O ""./" & $A11 & "_" & $N$1 & "_" & F$2 & ".csv""; sleep 4;" -> wget --user-agent Mozilla/4.0 http://k-db.com/indices/I114/4h/2010?download=csv -O "./TOPIX ミッド 400_前場後場_2010.csv"; sleep 4; | R11: ="wget --user-agent Mozilla/4.0 http://k-db.com" & $B11 & "/4h/" & R$2 & "?download=csv -O ""./" & $A11 & "_" & $N$1 & "_" & G$2 & ".csv""; sleep 4;" -> wget --user-agent Mozilla/4.0 http://k-db.com/indices/I114/4h/2011?download=csv -O "./TOPIX ミッド 400_前場後場_2011.csv"; sleep 4; | S11: ="wget --user-agent Mozilla/4.0 http://k-db.com" & $B11 & "/4h/" & S$2 & "?download=csv -O ""./" & $A11 & "_" & $N$1 & "_" & H$2 & ".csv""; sleep 4;" -> wget --user-agent Mozilla/4.0 http://k-db.com/indices/I114/4h/2012?download=csv -O "./TOPIX ミッド 400_前場後場_2012.csv"; sleep 4; | T11: ="wget --user-agent Mozilla/4.0 http://k-db.com" & $B11 & "/4h/" & T$2 & "?download=csv -O ""./" & $A11 & "_" & $N$1 & "_" & I$2 & ".csv""; sleep 4;" -> wget --user-agent Mozilla/4.0 http://k-db.com/indices/I114/4h/2013?download=csv -O "./TOPIX ミッド 400_前場後場_2013.csv"; sleep 4; | U11: ="wget --user-agent Mozilla/4.0 http://k-db.com" & $B11 & "/4h/" & U$2 & "?download=csv -O ""./" & $A11 & "_" & $N$1 & "_" & J$2 & ".csv""; sleep 4;" -> wget --user-agent Mozilla/4.0 http://k-db.com/indices/I114/4h/2014?download=csv -O "./TOPIX ミッド 400_前場後場_2014.csv"; sleep 4; | ... X11: ="wget --user-agent Mozilla/4.0 http://k-db.com" & $B11 & "/4h/" & X$2 & "?download=csv -O ""./" & $A11 & "_" & $N$1 & "_" & M$2 & ".csv""; sleep 4;" -> wget --user-agent Mozilla/4.0 http://k-db.com/indices/I114/4h/2017?download=csv -O "./TOPIX ミッド 400_前場後場_2017.csv"; sleep 4;
A12: TOPIX 500 | B12: /indices/I115 | C12: ="wget --user-agent Mozilla/4.0 http://k-db.com" & $B12 & "/1d/" & C$2 & "?download=csv -O ""./" & $A12 & "_" & $C$1 & "_" & C$2 & ".csv""; sleep 4;" -> wget --user-agent Mozilla/4.0 http://k-db.com/indices/I115/1d/2007?download=csv -O "./TOPIX 500_日足_2007.csv"; sleep 4; | D12: ="wget --user-agent Mozilla/4.0 http://k-db.com" & $B12 & "/1d/" & D$2 & "?download=csv -O ""./" & $A12 & "_" & $C$1 & "_" & D$2 & ".csv""; sleep 4;" -> wget --user-agent Mozilla/4.0 http://k-db.com/indices/I115/1d/2008?download=csv -O "./TOPIX 500_日足_2008.csv"; sleep 4; | E12: ="wget --user-agent Mozilla/4.0 http://k-db.com" & $B12 & "/1d/" & E$2 & "?download=csv -O ""./" & $A12 & "_" & $C$1 & "_" & E$2 & ".csv""; sleep 4;" -> wget --user-agent Mozilla/4.0 http://k-db.com/indices/I115/1d/2009?download=csv -O "./TOPIX 500_日足_2009.csv"; sleep 4; | F12: ="wget --user-agent Mozilla/4.0 http://k-db.com" & $B12 & "/1d/" & F$2 & "?download=csv -O ""./" & $A12 & "_" & $C$1 & "_" & F$2 & ".csv""; sleep 4;" -> wget --user-agent Mozilla/4.0 http://k-db.com/indices/I115/1d/2010?download=csv -O "./TOPIX 500_日足_2010.csv"; sleep 4; | G12: ="wget --user-agent Mozilla/4.0 http://k-db.com" & $B12 & "/1d/" & G$2 & "?download=csv -O ""./" & $A12 & "_" & $C$1 & "_" & G$2 & ".csv""; sleep 4;" -> wget --user-agent Mozilla/4.0 http://k-db.com/indices/I115/1d/2011?download=csv -O "./TOPIX 500_日足_2011.csv"; sleep 4; | H12: ="wget --user-agent Mozilla/4.0 http://k-db.com" & $B12 & "/1d/" & H$2 & "?download=csv -O ""./" & $A12 & "_" & $C$1 & "_" & H$2 & ".csv""; sleep 4;" -> wget --user-agent Mozilla/4.0 http://k-db.com/indices/I115/1d/2012?download=csv -O "./TOPIX 500_日足_2012.csv"; sleep 4; | I12: ="wget --user-agent Mozilla/4.0 http://k-db.com" & $B12 & "/1d/" & I$2 & "?download=csv -O ""./" & $A12 & "_" & $C$1 & "_" & I$2 & ".csv""; sleep 4;" -> wget --user-agent Mozilla/4.0 http://k-db.com/indices/I115/1d/2013?download=csv -O "./TOPIX 500_日足_2013.csv"; sleep 4; | J12: ="wget --user-agent Mozilla/4.0 http://k-db.com" & $B12 & "/1d/" & J$2 & "?download=csv -O ""./" & $A12 & "_" & $C$1 & "_" & J$2 & ".csv""; sleep 4;" -> wget --user-agent Mozilla/4.0 http://k-db.com/indices/I115/1d/2014?download=csv -O "./TOPIX 500_日足_2014.csv"; sleep 4; | ... M12: ="wget --user-agent Mozilla/4.0 http://k-db.com" & $B12 & "/1d/" & M$2 & "?download=csv -O ""./" & $A12 & "_" & $C$1 & "_" & M$2 & ".csv""; sleep 4;" -> wget --user-agent Mozilla/4.0 http://k-db.com/indices/I115/1d/2017?download=csv -O "./TOPIX 500_日足_2017.csv"; sleep 4; | N12: ="wget --user-agent Mozilla/4.0 http://k-db.com" & $B12 & "/4h/" & N$2 & "?download=csv -O ""./" & $A12 & "_" & $N$1 & "_" & C$2 & ".csv""; sleep 4;" -> wget --user-agent Mozilla/4.0 http://k-db.com/indices/I115/4h/2007?download=csv -O "./TOPIX 500_前場後場_2007.csv"; sleep 4; | O12: ="wget --user-agent Mozilla/4.0 http://k-db.com" & $B12 & "/4h/" & O$2 & "?download=csv -O ""./" & $A12 & "_" & $N$1 & "_" & D$2 & ".csv""; sleep 4;" -> wget --user-agent Mozilla/4.0 http://k-db.com/indices/I115/4h/2008?download=csv -O "./TOPIX 500_前場後場_2008.csv"; sleep 4; | P12: ="wget --user-agent Mozilla/4.0 http://k-db.com" & $B12 & "/4h/" & P$2 & "?download=csv -O ""./" & $A12 & "_" & $N$1 & "_" & E$2 & ".csv""; sleep 4;" -> wget --user-agent Mozilla/4.0 http://k-db.com/indices/I115/4h/2009?download=csv -O "./TOPIX 500_前場後場_2009.csv"; sleep 4; | Q12: ="wget --user-agent Mozilla/4.0 http://k-db.com" & $B12 & "/4h/" & Q$2 & "?download=csv -O ""./" & $A12 & "_" & $N$1 & "_" & F$2 & ".csv""; sleep 4;" -> wget --user-agent Mozilla/4.0 http://k-db.com/indices/I115/4h/2010?download=csv -O "./TOPIX 500_前場後場_2010.csv"; sleep 4; | R12: ="wget --user-agent Mozilla/4.0 http://k-db.com" & $B12 & "/4h/" & R$2 & "?download=csv -O ""./" & $A12 & "_" & $N$1 & "_" & G$2 & ".csv""; sleep 4;" -> wget --user-agent Mozilla/4.0 http://k-db.com/indices/I115/4h/2011?download=csv -O "./TOPIX 500_前場後場_2011.csv"; sleep 4; | S12: ="wget --user-agent Mozilla/4.0 http://k-db.com" & $B12 & "/4h/" & S$2 & "?download=csv -O ""./" & $A12 & "_" & $N$1 & "_" & H$2 & ".csv""; sleep 4;" -> wget --user-agent Mozilla/4.0 http://k-db.com/indices/I115/4h/2012?download=csv -O "./TOPIX 500_前場後場_2012.csv"; sleep 4; | T12: ="wget --user-agent Mozilla/4.0 http://k-db.com" & $B12 & "/4h/" & T$2 & "?download=csv -O ""./" & $A12 & "_" & $N$1 & "_" & I$2 & ".csv""; sleep 4;" -> wget --user-agent Mozilla/4.0 http://k-db.com/indices/I115/4h/2013?download=csv -O "./TOPIX 500_前場後場_2013.csv"; sleep 4; | U12: ="wget --user-agent Mozilla/4.0 http://k-db.com" & $B12 & "/4h/" & U$2 & "?download=csv -O ""./" & $A12 & "_" & $N$1 & "_" & J$2 & ".csv""; sleep 4;" -> wget --user-agent Mozilla/4.0 http://k-db.com/indices/I115/4h/2014?download=csv -O "./TOPIX 500_前場後場_2014.csv"; sleep 4; | ... X12: ="wget --user-agent Mozilla/4.0 http://k-db.com" & $B12 & "/4h/" & X$2 & "?download=csv -O ""./" & $A12 & "_" & $N$1 & "_" & M$2 & ".csv""; sleep 4;" -> wget --user-agent Mozilla/4.0 http://k-db.com/indices/I115/4h/2017?download=csv -O "./TOPIX 500_前場後場_2017.csv"; sleep 4;
